Workbook

Sheet kWh
B1: Monthly Solar Production (kWh)
A2: Month | B2: Alpharetta Library | C2: Wolf Creek Library | D2: Metropolitan Library | E2: Northwest Library | F2: Southeast Atlanta Library | G2: Neighbor-hood Union Health | H2: College Park Regional Health | I2: Milton Library | J2: E Roswell Library | K2: Maxwell Rd (Driver Services) | L2: Benson Senior Center | M2: Aviation Cultural Center | N2: Mills Senior Center | O2: Dogwood Library | P2: Palmetto Library | Q2: Cascade (SW) Library | R2: South Fulton Service Center | S2: Juvenile Justice Center | T2: Ponce de Leon (JP) Library | U2: New Beginnings Senior Center | V2: Medical Examiner | W2: Gladys Dennard Library | X2: Board of Health | Y2: Dogwood Senior Center | Z2: College Park Library | AA2: Animal Services | AB2: Adamsville (AC) Library | AC2: Union City Jail | AD2: Sandy Springs Library | AE2: QLS Senior Center | AF2: North Fulton Service Center | AG2: Bowden Senior Center | AH2: Cleveland Ave Library | AI2: Adams Park Library | AJ2: SE Neighborhood Senior Center | AK2: NE Spruill Oaks Library | AL2: Ocee Library | AM2: Auburn Ave Research Library | AN2: Buckhead Library | AO2: Hapeville Library | AP2: Northside Library | AQ2: Total kWh Produced | AR2: GRAND TOTAL | AS2: eGRID 2023 subregion SRSO CO2e non-baseload output emission rate (lb/MWh)* | AT2: CO2e savings (lbs)
A3: 44287 | B3: 5381.5 | C3: 7949.4 | D3: 9227.4 | AQ3: =SUM(B3:AP3) -> 22558.3 | AR3: =SUM(AQ3:AQ65) -> 6268705.5 | AS3: 1392.345 | AT3: =(AR3/1000)*AS3 -> 8728200.8
A4: 44317 | B4: 9979.5 | C4: 7421.6 | D4: 17443.5 | AQ4: =SUM(B4:AP4) -> 34844.6 | AR4: 6754479 | AS4: new contract annual production | AT4: =(AR4/1000)*AS3 -> 9404565.1
A5: 44348 | B5: 8841.6 | C5: 13795 | D5: 15438.5 | AQ5: =SUM(B5:AP5) -> 38075.1 | AR5: =AR4+AR24 -> 7430351.6 | AS5: new contract + old contract annual production | AT5: =(AR5/1000)*AS3 -> 10345613
A6: 44378 | B6: 8958.4 | C6: 14853.5 | D6: 13481.3 | AQ6: =SUM(B6:AP6) -> 37293.2
A7: 44409 | B7: 8525.9 | C7: 14590.1 | D7: 16984 | AQ7: =SUM(B7:AP7) -> 40100
A8: 44440 | B8: 7550 | C8: 5768 | D8: 12955 | AQ8: =SUM(B8:AP8) -> 26273
A9: 44470 | B9: 5992 | C9: 10166 | D9: 10833 | E9: 8631 | AQ9: =SUM(B9:AP9) -> 35622
A10: 44501 | B10: 5976 | C10: 9536 | D10: 10383 | E10: 8448 | AQ10: =SUM(B10:AP10) -> 34343
A11: 44531 | B11: 3433 | C11: 5510 | D11: 5840 | E11: 4706 | F11: 1895 | G11: 1019 | AQ11: =SUM(B11:AP11) -> 22403
A12: 44562 | B12: 4838 | C12: 8237 | D12: 8604 | E12: 6926 | F12: 2778 | G12: 1516 | AQ12: =SUM(B12:AP12) -> 32899
A13: 44593 | B13: 5841 | C13: 9450 | D13: 9516 | E13: 7862 | F13: 3194 | G13: 1693 | AQ13: =SUM(B13:AP13) -> 37556
A14: 44621 | B14: 8254 | C14: 13793 | D14: 13869 | E14: 11038 | F14: 4515 | G14: 2394 | H14: 7131 | AQ14: =SUM(B14:AP14) -> 60994
A15: 44652 | B15: 8739 | C15: 13528 | D15: 14933 | E15: 12025 | F15: 4886 | G15: 2518 | H15: 17360 | AQ15: =SUM(B15:AP15) -> 73989
A16: 44682 | B16: 9591 | C16: 16181 | D16: 16227 | E16: 13081 | F16: 5558 | G16: 2746 | H16: 18826 | AQ16: =SUM(B16:AP16) -> 82210
A17: 44713 | B17: 9640 | C17: 16489 | D17: 16606 | E17: 13004 | F17: 5671 | G17: 2765 | H17: 18856 | AQ17: =SUM(B17:AP17) -> 83031
A18: 44743 | B18: 9142.2 | C18: 13914.4 | D18: 15278.1 | E18: 12245.5 | F18: 5167.4 | G18: 2611.9 | H18: 17138.2 | AQ18: =SUM(B18:AP18) -> 75497.7
A19: 44774 | B19: 7930.2 | C19: 12070.1 | D19: 13425.4 | E19: 11128.6 | F19: 4523.3 | G19: 2238.9 | H19: 14986.6 | AQ19: =SUM(B19:AP19) -> 66303.1
A20: 44805 | B20: 8079 | C20: 11923.2 | D20: 13572.8 | E20: 11063.9 | F20: 4483.1 | G20: 2237.3 | H20: 15815.8 | AQ20: =SUM(B20:AP20) -> 67175.1
A21: 44835 | B21: 7320.8 | C21: 12183 | D21: 12607.2 | E21: 10220 | F21: 4092.4 | G21: 2081.5 | H21: 15067.1 | AQ21: =SUM(B21:AP21) -> 63572
A22: 44866 | B22: 4758.8 | C22: 8073.9 | D22: 8333 | E22: 6727.7 | F22: 2715 | G22: 1429.3 | H22: 7459.6 | AQ22: =SUM(B22:AP22) -> 39497.3
A23: 44896 | B23: 3421.2 | C23: 5974 | D23: 6125 | E23: 4857.7 | F23: 1958.8 | G23: 1059.3 | H23: 7467.5 | AQ23: =SUM(B23:AP23) -> 30863.5
A24: 44927 | B24: 3936.6 | C24: 7082.8 | D24: 6992 | E24: 5536.9 | F24: 2293.8 | G24: 1196.5 | H24: 8696 | AQ24: =SUM(B24:AP24) -> 35734.6 | AR24: =SUM(AQ24:AQ35) -> 675872.6 | AS24: 2023 kWh total | AT24: =(AR24/1000)*AS3 -> 941047.84
A25: 44958 | B25: 4473 | C25: 7822 | D25: 7758 | E25: 6120 | F25: 2647 | G25: 1333 | H25: 9378 | AQ25: =SUM(B25:AP25) -> 39531
A26: 44986 | B26: 7353 | C26: 12153 | D26: 12363 | E26: 9842 | F26: 4281 | G26: 2138 | H26: 14772 | AQ26: =SUM(B26:AP26) -> 62902
A27: 45017 | B27: 8095 | C27: 12271 | D27: 13353 | E27: 10433 | F27: 4667 | G27: 2310 | H27: 15654 | AQ27: =SUM(B27:AP27) -> 66783
A28: 45047 | B28: 8809 | C28: 11812 | D28: 14007 | E28: 10883 | F28: 4954 | G28: 2488 | H28: 15854 | AQ28: =SUM(B28:AP28) -> 68807
A29: 45078 | B29: 8448 | C29: 12311 | D29: 14118 | E29: 11166 | F29: 4969 | G29: 2640 | H29: 16247 | AQ29: =SUM(B29:AP29) -> 69899
A30: 45108 | B30: 9191 | C30: 15058 | D30: 15714 | E30: 12103 | F30: 5394 | G30: 2679 | H30: 17843 | AQ30: =SUM(B30:AP30) -> 77982
A31: 45139 | B31: 8229 | C31: 13738 | D31: 13782 | E31: 10940 | F31: 4872 | G31: 2538 | H31: 16100 | AQ31: =SUM(B31:AP31) -> 70199
A32: 45170 | B32: 7339 | C32: 11143 | D32: 11878 | E32: 9589 | F32: 4114 | G32: 2150 | H32: 13717 | AQ32: =SUM(B32:AP32) -> 59930
A33: 45200 | B33: 6248 | C33: 9426 | D33: 10278 | E33: 8301 | F33: 3520 | G33: 1888 | H33: 12501 | AQ33: =SUM(B33:AP33) -> 52162
A34: 45231 | B34: 4633 | C34: 7048 | D34: 7802 | E34: 6177 | F34: 2649 | G34: 1413 | H34: 9258 | AQ34: =SUM(B34:AP34) -> 38980
A35: 45261 | B35: 3821 | C35: 6048 | D35: 6564 | E35: 5126 | F35: 2194 | G35: 1179 | H35: 8031 | AQ35: =SUM(B35:AP35) -> 32963
A36: 45292 | B36: 4404 | C36: 7365 | D36: 7571 | E36: 5884 | F36: 2544 | G36: 1369 | H36: 9262 | AQ36: =SUM(B36:AP36) -> 38399
... A51: 45748 | B51: 7940 | C51: 12616 | D51: 14164 | E51: 11205 | F51: 4590 | G51: 2335 | H51: 15237 | AQ51: =SUM(B51:AP51) -> 68087
A52: 45778 | B52: 7624 | C52: 9775 | D52: 13736 | E52: 10941 | F52: 4463 | G52: 2287 | H52: 14704 | I52: 1508 | J52: 1943 | K52: 2652 | L52: 4519 | M52: 554 | AQ52: =SUM(B52:AP52) -> 74706
A53: 45809 | B53: 8622 | C53: 10064 | D53: 13705 | E53: 11886 | F53: 4765 | G53: 2415 | H53: 14941 | I53: 4618 | J53: 12205 | K53: 37032 | L53: 19655 | M53: 5857 | N53: 4615 | O53: 1678 | Q53: 17422 | AQ53: =SUM(B53:AP53) -> 169480
A54: 45839 | B54: 9507 | C54: 11187 | D54: 14317 | E54: 10126 | F54: 5352 | G54: 2591 | H54: 17268 | I54: 5006 | J54: 13261 | K54: 40651 | L54: 20886 | M54: 8218 | N54: 18601 | O54: 3523 | Q54: 20773 | T54: 2997 | X54: 5823 | Y54: 3322 | AA54: 21553 | AB54: 2094 | AQ54: =SUM(B54:AP54) -> 237056
...

Sheet Elec Rates
B1: Monthly Electric Utility Rates ($/kWh)
A2: Month | B2: Alpharetta Library (GP) | C2: Wolf Creek Library (GreyStone) | D2: Metropolitan Library (GP) | E2: Northwest Library (GP) | F2: Southeast Atlanta Library (GP) | G2: Neighbor-hood Union Health (GP) | H2: College Park Health (College Park) | I2: Milton Library | J2: E Roswell Library | K2: Maxwell Rd (Driver Services) | L2: Benson Senior Center | M2: Aviation Cultural Center | N2: Mills Senior Center | O2: Dogwood Library | P2: Palmetto Library | Q2: Cascade (SW) Library | R2: South Fulton Service Center | S2: Juvenile Justice Center | T2: Ponce de Leon (JP) Library | U2: New Beginnings Senior Center | V2: Medical Examiner | W2: Gladys Dennard Library | X2: Board of Health | Y2: Dogwood Senior Center | Z2: College Park Library | AA2: Animal Services | AB2: Adamsville (AC) Library | AC2: Union City Jail | AD2: Sandy Springs Library | AE2: QLS Senior Center | AF2: North Fulton Service Center | AG2: Bowden Senior Center | AH2: Cleveland Ave Library | AI2: Adams Park Library | AJ2: SE Neighborhood Senior Center | AK2: NE Spruill Oaks Library | AL2: Ocee Library | AM2: Auburn Ave Research Library | AN2: Buckhead Library | AO2: Hapeville Library | AP2: Northside Library | AQ2: AVERAGE
A3: 44287 | B3: 0.142 | C3: 0.11 | D3: 0.096 | AQ3: =AVERAGE(B3:AP3) -> 0.116
A4: 44317 | B4: 0.142 | C4: 0.105 | D4: 0.098 | AQ4: =AVERAGE(B4:AP4) -> 0.115
A5: 44348 | B5: 0.182 | C5: 0.1 | D5: 0.13 | AQ5: =AVERAGE(B5:AP5) -> 0.13733333
A6: 44378 | B6: 0.134 | C6: 0.105 | D6: 0.119 | AQ6: =AVERAGE(B6:AP6) -> 0.11933333
A7: 44409 | B7: 0.168 | C7: 0.096 | D7: 0.133 | AQ7: =AVERAGE(B7:AP7) -> 0.13233333
A8: 44440 | B8: 0.169 | C8: 0.083 | D8: 0.129 | AQ8: =AVERAGE(B8:AP8) -> 0.127
A9: 44470 | B9: 0.097 | C9: 0.112 | D9: 0.088 | E9: 0.102 | AQ9: =AVERAGE(B9:AP9) -> 0.09975
A10: 44501 | B10: 0.09 | C10: 0.099 | D10: 0.088 | E10: 0.102 | AQ10: =AVERAGE(B10:AP10) -> 0.09475
A11: 44531 | B11: 0.094 | C11: 0.095 | D11: 0.087 | E11: 0.108 | F11: 0.157 | G11: 0.168 | AQ11: =AVERAGE(B11:AP11) -> 0.11816667
A12: 44562 | B12: 0.114 | C12: 0.096 | D12: 0.088 | E12: 0.152 | F12: 0.161 | G12: 0.103 | AQ12: =AVERAGE(B12:AP12) -> 0.119
A13: 44593 | B13: 0.114 | C13: 0.107 | D13: 0.088 | E13: 0.152 | F13: 0.156 | G13: 0.158 | AQ13: =AVERAGE(B13:AP13) -> 0.12916667
A14: 44621 | B14: 0.122 | C14: 0.112 | D14: 0.088 | E14: 0.093 | F14: 0.168 | G14: 0.102 | H14: 0.142 | AQ14: =AVERAGE(B14:AP14) -> 0.11814286
A15: 44652 | B15: 0.122 | C15: 0.098 | D15: 0.088 | E15: 0.09 | F15: 0.173 | G15: 0.103 | H15: 0.15 | AQ15: =AVERAGE(B15:AP15) -> 0.11771429
A16: 44682 | B16: 0.1 | C16: 0.109 | D16: 0.088 | E16: 0.088 | F16: 0.176 | G16: 0.089 | H16: 0.152 | AQ16: =AVERAGE(B16:AP16) -> 0.11457143
A17: 44713 | B17: 0.229 | C17: 0.104 | D17: 0.136 | E17: 0.168 | F17: 0.164 | G17: 0.163 | H17: 0.146 | AQ17: =AVERAGE(B17:AP17) -> 0.15857143
A18: 44743 | B18: 0.185 | C18: 0.094 | D18: 0.126 | E18: 0.151 | F18: 0.161 | G18: 0.158 | H18: 0.145 | AQ18: =AVERAGE(B18:AP18) -> 0.14571429
A19: 44774 | B19: 0.167 | C19: 0.103 | D19: 0.137 | E19: 0.145 | F19: 0.164 | G19: 0.162 | H19: 0.143 | AQ19: =AVERAGE(B19:AP19) -> 0.14585714
A20: 44805 | B20: 0.178 | C20: 0.112 | D20: 0.138 | E20: 0.143 | F20: 0.165 | G20: 0.167 | H20: 0.144 | AQ20: =AVERAGE(B20:AP20) -> 0.14957143
A21: 44835 | B21: 0.108 | C21: 0.114 | D21: 0.088 | E21: 0.089 | F21: 0.169 | G21: 0.099 | H21: 0.152 | AQ21: =AVERAGE(B21:AP21) -> 0.117
A22: 44866 | B22: 0.103 | C22: 0.118 | D22: 0.087 | E22: 0.09 | F22: 0.166 | G22: 0.097 | H22: 0.155 | AQ22: =AVERAGE(B22:AP22) -> 0.11657143
A23: 44896 | B23: 0.1 | C23: 0.122 | D23: 0.087 | E23: 0.096 | F23: 0.156 | G23: 0.098 | H23: 0.141 | AQ23: =AVERAGE(B23:AP23) -> 0.11428571
A24: 44927 | B24: 0.103 | C24: 0.136 | D24: 0.086 | E24: 0.095 | F24: 0.165 | G24: 0.1 | H24: 0.143 | AQ24: =AVERAGE(B24:AP24) -> 0.11828571
A25: 44958 | B25: 0.109 | C25: 0.146 | D25: 0.093 | E25: 0.091 | F25: 0.174 | G25: 0.101 | H25: 0.141 | AQ25: =AVERAGE(B25:AP25) -> 0.12214286
... A51: 45748 | B51: 0.128 | C51: 0.102 | D51: 0.115 | E51: 0.141 | F51: 0.224 | G51: 0.135 | H51: 0.136 | AQ51: =AVERAGE(B51:AP51) -> 0.14014286
A52: 45778 | B52: 0.123 | C52: 0.116 | D52: 0.115 | E52: 0.13 | F52: 0.225 | G52: 0.128 | H52: 0.13 | I52: 0.117 | J52: 0.128 | K52: 0.131 | L52: 0.14 | M52: 0.215 | N52: 0.164 | O52: 0.125 | Q52: 0.109 | R52: 0.158 | S52: 0.103 | T52: 0.2 | U52: 0.145 | V52: 0.137 | W52: 0.166 | X52: 0.195 | AQ52: =AVERAGE(B52:AP52) -> 0.14545455
A53: 45809 | B53: 0.201 | C53: 0.109 | D53: 0.186 | E53: 0.229 | F53: 0.219 | G53: 0.215 | H53: 0.129 | I53: 0.084 | J53: 0.149 | K53: 0.168 | L53: 0.146 | M53: 0.213 | N53: 0.147 | O53: 0.221 | Q53: 0.134 | R53: 0.14 | S53: 0.116 | T53: 0.177 | U53: 0.129 | V53: 0.131 | W53: 0.159 | X53: 0.199 | AQ53: =AVERAGE(B53:AP53) -> 0.16368182
A54: 45839 | B54: 0.19 | C54: 0.106 | D54: 0.18 | E54: 0.223 | F54: 0.214 | G54: 0.223 | H54: 0.131 | I54: 0.149 | J54: 0.129 | K54: 0.165 | L54: 0.146 | M54: 0.21 | N54: 0.15 | O54: 0.212 | Q54: 0.132 | R54: 0.133 | S54: 0.127 | T54: 0.192 | U54: 0.123 | V54: 0.125 | W54: 0.132 | X54: 0.196 | Y54: 0.238 | Z54: 0.142 | AA54: 0.123 | AB54: 0.218 | AC54: 0.112 | AD54: 0.173 | AE54: 0.171 | AF54: 0.124 | AG54: 0.108 | AH54: 0.182 | AI54: 0.144 | AJ54: 0.217 | AQ54: =AVERAGE(B54:AP54) -> 0.16294118
A55: 45870 | B55: 0.185 | C55: 0.109 | D55: 0.176 | E55: 0.241 | F55: 0.218 | G55: 0.229 | H55: 0.125 | I55: 0.146 | J55: 0.137 | K55: 0.15 | L55: 0.139 | M55: 0.221 | N55: 0.154 | O55: 0.22 | Q55: 0.156 | R55: 0.134 | S55: 0.11 | T55: 0.242 | U55: 0.144 | V55: 0.125 | W55: 0.17 | X55: 0.199 | Y55: 0.251 | Z55: 0.141 | AA55: 0.125 | AB55: 0.221 | AC55: 0.115 | AD55: 0.19 | AE55: 0.174 | AF55: 0.137 | AG55: 0.126 | AH55: 0.177 | AI55: 0.149 | AJ55: 0.212 | AQ55: =AVERAGE(B55:AP55) -> 0.16905882
A56: 45901 | B56: 0.184 | C56: 0.107 | D56: 0.165 | E56: 0.223 | F56: 0.221 | G56: 0.224 | H56: 0.15 | I56: 0.116 | J56: 0.137 | K56: 0.153 | L56: 0.139 | M56: 0.222 | N56: 0.164 | O56: 0.223 | Q56: 0.149 | R56: 0.135 | S56: 0.116 | T56: 0.238 | U56: 0.193 | V56: 0.125 | W56: 0.16 | X56: 0.201 | Y56: 0.233 | Z56: 0.174 | AA56: 0.108 | AB56: 0.221 | AC56: 0.127 | AD56: 0.216 | AE56: 0.202 | AF56: 0.137 | AG56: 0.126 | AH56: 0.188 | AI56: 0.187 | AJ56: 0.237 | AQ56: =AVERAGE(B56:AP56) -> 0.17355882
A57: 45931 | B57: 0.122 | C57: 0.123 | D57: 0.111 | E57: 0.132 | F57: 0.221 | G57: 0.14 | H57: 0.125 | I57: 0.125 | J57: 0.135 | K57: 0.146 | L57: 0.146 | M57: 0.225 | N57: 0.157 | O57: 0.14 | Q57: 0.146 | R57: 0.153 | S57: 0.117 | T57: 0.244 | U57: 0.152 | V57: 0.151 | W57: 0.185 | X57: 0.198 | Y57: 0.243 | Z57: 0.175 | AA57: 0.117 | AB57: 0.134 | AC57: 0.128 | AD57: 0.214 | AE57: 0.205 | AF57: 0.135 | AG57: 0.128 | AH57: 0.241 | AI57: 0.162 | AJ57: 0.241 | AQ57: =AVERAGE(B57:AP57) -> 0.16226471
A58: 45962 | B58: 0.118 | C58: 0.121 | D58: 0.115 | E58: 0.125 | F58: 0.213 | G58: 0.14 | H58: 0.122 | I58: 0.206 | J58: 0.138 | K58: 0.142 | L58: 0.138 | M58: 0.212 | N58: 0.16 | O58: 0.151 | Q58: 0.192 | R58: 0.19 | S58: 0.131 | T58: 0.235 | U58: 0.15 | V58: 0.158 | W58: 0.169 | X58: 0.183 | Y58: 0.246 | Z58: 0.139 | AA58: 0.14 | AB58: 0.126 | AC58: 0.168 | AD58: 0.212 | AE58: 0.22 | AF58: 0.131 | AG58: 0.148 | AH58: 0.205 | AI58: 0.126 | AJ58: 0.295 | AQ58: =AVERAGE(B58:AP58) -> 0.16661765
A59: 45992 | B59: 0.115 | C59: 0.121 | D59: 0.114 | E59: 0.13 | F59: 0.184 | G59: 0.142 | H59: 0.135 | I59: 0.121 | J59: 0.112 | K59: 0.128 | L59: 0.113 | M59: 0.176 | N59: 0.178 | O59: 0.167 | P59: 0.114 | Q59: 0.131 | R59: 0.179 | S59: 0.131 | T59: 0.215 | U59: 0.15 | V59: 0.175 | W59: 0.16 | X59: 0.139 | Y59: 0.256 | Z59: 0.137 | AA59: 0.148 | AB59: 0.118 | AC59: 0.184 | AD59: 0.212 | AE59: 0.211 | AF59: 0.156 | AG59: 0.149 | AH59: 0.239 | AI59: 0.117 | AJ59: 0.235 | AQ59: =AVERAGE(B59:AP59) -> 0.15691429
A60: 46023 | B60: 0.116 | C60: 0.11 | D60: 0.115 | E60: 0.119 | F60: 0.174 | G60: 0.139 | H60: 0.128 | I60: 0.151 | J60: 0.118 | K60: 0.121 | L60: 0.111 | M60: 0.16 | N60: 0.172 | O60: 0.141 | P60: 0.113 | Q60: 0.15 | R60: 0.194 | S60: 0.125 | T60: 0.205 | U60: 0.155 | V60: 0.165 | W60: 0.146 | X60: 0.145 | Y60: 0.252 | Z60: 0.129 | AA60: 0.154 | AB60: 0.115 | AC60: 0.177 | AD60: 0.212 | AE60: 0.225 | AF60: 0.158 | AG60: 0.149 | AH60: 0.244 | AI60: 0.115 | AJ60: 0.226 | AK60: 0.12 | AL60: 0.1 | AQ60: =AVERAGE(B60:AP60) -> 0.15267568
A61: 46054 | B61: 0.121 | C61: 0.121 | D61: 0.116 | E61: 0.12 | F61: 0.204 | G61: 0.142 | H61: 0.13 | I61: 0.156 | J61: 0.124 | K61: 0.145 | L61: 0.113 | M61: 0.175 | N61: 0.197 | O61: 0.159 | P61: 0.121 | Q61: 0.171 | R61: 0.2 | S61: 0.128 | T61: 0.241 | U61: 0.18 | V61: 0.172 | W61: 0.172 | X61: 0.143 | Y61: 0.244 | Z61: 0.177 | AA61: 0.169 | AB61: 0.119 | AC61: 0.192 | AD61: 0.217 | AE61: 0.224 | AF61: 0.161 | AG61: 0.15 | AH61: 0.243 | AI61: 0.126 | AJ61: 0.229 | AK61: 0.122 | AL61: 0.102 | AN61: 0.182 | AQ61: =AVERAGE(B61:AP61) -> 0.16336842
A62: 46082 | B62: 0.12 | C62: 0.126 | D62: 0.119 | E62: 0.114 | F62: 0.221 | G62: 0.137 | H62: 0.13 | I62: 0.163 | J62: 0.139 | K62: 0.14 | L62: 0.117 | M62: 0.172 | N62: 0.179 | O62: 0.146 | P62: 0.134 | Q62: 0.147 | R62: 0.197 | S62: 0.13 | T62: 0.238 | U62: 0.112 | V62: 0.156 | W62: 0.185 | X62: 0.192 | Y62: 0.215 | Z62: 0.154 | AA62: 0.143 | AB62: 0.118 | AC62: 0.18 | AD62: 0.213 | AE62: 0.217 | AF62: 0.136 | AG62: 0.144 | AH62: 0.236 | AI62: 0.145 | AJ62: 0.217 | AK62: 0.117 | AL62: 0.097 | AN62: 0.202 | AP62: 0.212 | AQ62: =AVERAGE(B62:AP62) -> 0.16051282
A63: 46113 | B63: 0.125 | C63: 0.119 | D63: 0.113 | E63: 0.139 | F63: 0.227 | G63: 0.141 | H63: 0.127 | I63: 0.137 | J63: 0.138 | K63: 0.152 | L63: 0.133 | M63: 0.213 | N63: 0.165 | O63: 0.143 | P63: 0.113 | Q63: 0.143 | R63: 0.187 | S63: 0.107 | T63: 0.238 | U63: 0.092 | V63: 0.167 | W63: 0.201 | X63: 0.181 | Y63: 0.17 | Z63: 0.144 | AA63: 0.136 | AB63: 0.126 | AC63: 0.156 | AD63: 0.219 | AE63: 0.222 | AF63: 0.139 | AG63: 0.144 | AH63: 0.238 | AI63: 0.166 | AJ63: 0.204 | AK63: 0.128 | AL63: 0.098 | AN63: 0.217 | AO63: 0.152 | AP63: 0.209 | AQ63: =AVERAGE(B63:AP63) -> 0.159225
A64: 46143 | B64: 0.117 | C64: 0.112 | D64: 0.108 | E64: 0.123 | F64: 0.212 | G64: 0.132 | H64: 0.119 | I64: 0.119 | J64: 0.133 | K64: 0.15 | L64: 0.125 | M64: 0.187 | N64: 0.143 | O64: 0.124 | P64: 0.123 | Q64: 0.164 | R64: 0.174 | S64: 0.112 | T64: 0.22 | U64: 0.133 | V64: 0.152 | W64: 0.199 | X64: 0.168 | Y64: 0.187 | Z64: 0.153 | AA64: 0.124 | AB64: 0.119 | AC64: 0.148 | AD64: 0.213 | AE64: 0.216 | AF64: 0.127 | AG64: 0.124 | AH64: 0.234 | AI64: 0.179 | AJ64: 0.248 | AK64: 0.126 | AL64: 0.104 | AM64: 0.125 | AN64: 0.208 | AO64: 0.151 | AP64: 0.223 | AQ64: =AVERAGE(B64:AP64) -> 0.15507317
A65: 46174 | B65: 0.188 | C65: 0.112 | D65: 0.174 | E65: 0.215 | F65: 0.214 | G65: 0.219 | H65: 0.119 | I65: 0.124 | J65: 0.133 | K65: 0.156 | L65: 0.127 | M65: 0.174 | N65: 0.137 | O65: 0.216 | P65: 0.123 | Q65: 0.183 | R65: 0.144 | S65: 0.107 | T65: 0.23 | U65: 0.133 | V65: 0.145 | W65: 0.198 | X65: 0.168 | Y65: 0.211 | Z65: 0.153 | AA65: 0.105 | AB65: 0.215 | AC65: 0.131 | AD65: 0.215 | AE65: 0.212 | AF65: 0.132 | AG65: 0.124 | AH65: 0.237 | AI65: 0.196 | AJ65: 0.225 | AK65: 0.126 | AL65: 0.104 | AM65: 0.14 | AN65: 0.158 | AO65: 0.237 | AP65: 0.225 | AQ65: =AVERAGE(B65:AP65) -> 0.16792683
...

Sheet CS Rates
A1: Monthly Cherry Street Rates ($/kWh)
A2: Month | B2: Alpharetta Library | C2: Wolf Creek Library | D2: Metropolitan Library | E2: Northwest Library | F2: Southeast Atlanta Library | G2: Neighbor-hood Union Health | H2: College Park Regional Health | I2: Milton Library | J2: E Roswell Library | K2: Maxwell Rd (Driver Services) | L2: Benson Senior Center | M2: Aviation Cultural Center | N2: Mills Senior Center | O2: Dogwood Library | P2: Palmetto Library | Q2: Cascade (SW) Library | R2: South Fulton Service Center | S2: Juvenile Justice Center | T2: Ponce de Leon (JP) Library | U2: New Beginnings Senior Center | V2: Medical Examiner | W2: Gladys Dennard Library | X2: Board of Health | Y2: Dogwood Senior Center | Z2: College Park Library | AA2: Animal Services | AB2: Adamsville (AC) Library | AC2: Union City Jail | AD2: Sandy Springs Library | AE2: QLS Senior Center | AF2: North Fulton Service Center | AG2: Bowden Senior Center | AH2: Cleveland Ave Library | AI2: Adams Park Library | AJ2: SE Neighborhood Senior Center | AK2: NE Spruill Oaks Library | AL2: Ocee Library | AM2: Auburn Ave Research Library | AN2: Buckhead Library | AO2: Hapeville Library | AP2: Northside Library | AQ2: AVERAGE
A3: 44287 | B3: 0.07 | C3: 0.07 | D3: 0.07 | AQ3: =AVERAGE(B3:AP3) -> 0.07
A4: 44317 | B4: 0.07 | C4: 0.07 | D4: 0.07 | AQ4: =AVERAGE(B4:AP4) -> 0.07
A5: 44348 | B5: 0.07 | C5: 0.07 | D5: 0.07 | AQ5: =AVERAGE(B5:AP5) -> 0.07
A6: 44378 | B6: 0.07 | C6: 0.07 | D6: 0.07 | AQ6: =AVERAGE(B6:AP6) -> 0.07
A7: 44409 | B7: 0.07 | C7: 0.07 | D7: 0.07 | AQ7: =AVERAGE(B7:AP7) -> 0.07
A8: 44440 | B8: 0.07 | C8: 0.07 | D8: 0.07 | AQ8: =AVERAGE(B8:AP8) -> 0.07
A9: 44470 | B9: 0.07 | C9: 0.07 | D9: 0.07 | E9: 0.07 | AQ9: =AVERAGE(B9:AP9) -> 0.07
A10: 44501 | B10: 0.07 | C10: 0.07 | D10: 0.07 | E10: 0.07 | AQ10: =AVERAGE(B10:AP10) -> 0.07
A11: 44531 | B11: 0.07 | C11: 0.07 | D11: 0.07 | E11: 0.07 | F11: 0.07 | G11: 0.07 | AQ11: =AVERAGE(B11:AP11) -> 0.07
A12: 44562 | B12: 0.07 | C12: 0.07 | D12: 0.07 | E12: 0.07 | F12: 0.07 | G12: 0.07 | AQ12: =AVERAGE(B12:AP12) -> 0.07
A13: 44593 | B13: 0.07 | C13: 0.07 | D13: 0.07 | E13: 0.07 | F13: 0.07 | G13: 0.07 | AQ13: =AVERAGE(B13:AP13) -> 0.07
A14: 44621 | B14: 0.07 | C14: 0.07 | D14: 0.07 | E14: 0.07 | F14: 0.07 | G14: 0.07 | H14: 0.07 | AQ14: =AVERAGE(B14:AP14) -> 0.07
A15: 44652 | B15: 0.0711 | C15: 0.0711 | D15: 0.0711 | E15: 0.07 | F15: 0.07 | G15: 0.07 | H15: 0.07 | AQ15: =AVERAGE(B15:AP15) -> 0.070471429
A16: 44682 | B16: 0.0711 | C16: 0.0711 | D16: 0.0711 | E16: 0.07 | F16: 0.07 | G16: 0.07 | H16: 0.07 | AQ16: =AVERAGE(B16:AP16) -> 0.070471429
A17: 44713 | B17: 0.0711 | C17: 0.0711 | D17: 0.0711 | E17: 0.07 | F17: 0.07 | G17: 0.07 | H17: 0.07 | AQ17: =AVERAGE(B17:AP17) -> 0.070471429
A18: 44743 | B18: 0.0711 | C18: 0.0711 | D18: 0.0711 | E18: 0.07 | F18: 0.07 | G18: 0.07 | H18: 0.07 | AQ18: =AVERAGE(B18:AP18) -> 0.070471429
A19: 44774 | B19: 0.0711 | C19: 0.0711 | D19: 0.0711 | E19: 0.07 | F19: 0.07 | G19: 0.07 | H19: 0.07 | AQ19: =AVERAGE(B19:AP19) -> 0.070471429
A20: 44805 | B20: 0.0711 | C20: 0.0711 | D20: 0.0711 | E20: 0.07 | F20: 0.07 | G20: 0.07 | H20: 0.07 | AQ20: =AVERAGE(B20:AP20) -> 0.070471429
A21: 44835 | B21: 0.0711 | C21: 0.0711 | D21: 0.0711 | E21: 0.0711 | F21: 0.07 | G21: 0.07 | H21: 0.07 | AQ21: =AVERAGE(B21:AP21) -> 0.070628571
A22: 44866 | B22: 0.0711 | C22: 0.0711 | D22: 0.0711 | E22: 0.0711 | F22: 0.07 | G22: 0.07 | H22: 0.07 | AQ22: =AVERAGE(B22:AP22) -> 0.070628571
A23: 44896 | B23: 0.0711 | C23: 0.0711 | D23: 0.0711 | E23: 0.0711 | F23: 0.0711 | G23: 0.0711 | H23: 0.07 | AQ23: =AVERAGE(B23:AP23) -> 0.070942857
A24: 44927 | B24: 0.0711 | C24: 0.0711 | D24: 0.0711 | E24: 0.0711 | F24: 0.0711 | G24: 0.0711 | H24: 0.07 | AQ24: =AVERAGE(B24:AP24) -> 0.070942857
A25: 44958 | B25: 0.0711 | C25: 0.0711 | D25: 0.0711 | E25: 0.0711 | F25: 0.0711 | G25: 0.0711 | H25: 0.07 | AQ25: =AVERAGE(B25:AP25) -> 0.070942857
... A51: 45748 | B51: 0.0743 | C51: 0.0743 | D51: 0.0743 | E51: 0.0732 | F51: 0.0732 | G51: 0.0732 | H51: 0.0732 | AQ51: =AVERAGE(B51:AP51) -> 0.073671429
A52: 45778 | B52: 0.0743 | C52: 0.0743 | D52: 0.0743 | E52: 0.0732 | F52: 0.0732 | G52: 0.0732 | H52: 0.0732 | I52: 0.115 | J52: 0.115 | K52: 0.115 | L52: 0.115 | M52: 0.115 | AQ52: =AVERAGE(B52:AP52) -> 0.090891667
A53: 45809 | B53: 0.0743 | C53: 0.0743 | D53: 0.0743 | E53: 0.0732 | F53: 0.0732 | G53: 0.0732 | H53: 0.0732 | I53: 0.115 | J53: 0.115 | K53: 0.115 | L53: 0.115 | M53: 0.115 | N53: 0.115 | O53: 0.115 | Q53: 0.115 | AQ53: =AVERAGE(B53:AP53) -> 0.095713333
A54: 45839 | B54: 0.0743 | C54: 0.0743 | D54: 0.0743 | E54: 0.0732 | F54: 0.0732 | G54: 0.0732 | H54: 0.0732 | I54: 0.115 | J54: 0.115 | K54: 0.115 | L54: 0.115 | M54: 0.115 | N54: 0.115 | O54: 0.115 | Q54: 0.115 | T54: 0.115 | X54: 0.115 | Y54: 0.115 | AA54: 0.115 | AB54: 0.115 | AQ54: =AVERAGE(B54:AP54) -> 0.100535
A55: 45870 | B55: 0.0743 | C55: 0.0743 | D55: 0.0743 | E55: 0.0732 | F55: 0.0732 | G55: 0.0732 | H55: 0.0732 | I55: 0.115 | J55: 0.115 | K55: 0.115 | L55: 0.115 | M55: 0.115 | N55: 0.115 | O55: 0.115 | Q55: 0.115 | S55: 0.115 | T55: 0.115 | X55: 0.115 | Y55: 0.115 | Z55: 0.115 | AA55: 0.115 | AB55: 0.115 | AQ55: =AVERAGE(B55:AP55) -> 0.10185
A56: 45901 | B56: 0.0743 | C56: 0.0743 | D56: 0.0743 | E56: 0.0732 | F56: 0.0732 | G56: 0.0732 | H56: 0.0732 | I56: 0.115 | J56: 0.115 | K56: 0.115 | L56: 0.115 | M56: 0.115 | N56: 0.115 | O56: 0.115 | Q56: 0.115 | R56: 0.115 | S56: 0.115 | T56: 0.115 | U56: 0.115 | V56: 0.115 | W56: 0.115 | X56: 0.115 | Y56: 0.115 | Z56: 0.115 | AA56: 0.115 | AB56: 0.115 | AQ56: =AVERAGE(B56:AP56) -> 0.10387308
A57: 45931 | B57: 0.0743 | C57: 0.0743 | D57: 0.0743 | E57: 0.0743 | F57: 0.0732 | G57: 0.0732 | H57: 0.0732 | I57: 0.115 | J57: 0.115 | K57: 0.115 | L57: 0.115 | M57: 0.115 | N57: 0.115 | O57: 0.115 | Q57: 0.115 | R57: 0.115 | S57: 0.115 | T57: 0.115 | U57: 0.115 | V57: 0.115 | W57: 0.115 | X57: 0.115 | Y57: 0.115 | Z57: 0.115 | AA57: 0.115 | AB57: 0.115 | AD57: 0.115 | AE57: 0.115 | AI57: 0.115 | AQ57: =AVERAGE(B57:AP57) -> 0.10506207
A58: 45962 | B58: 0.0743 | C58: 0.0743 | D58: 0.0743 | E58: 0.0743 | F58: 0.0732 | G58: 0.0732 | H58: 0.0732 | I58: 0.115 | J58: 0.115 | K58: 0.115 | L58: 0.115 | M58: 0.115 | N58: 0.115 | O58: 0.115 | Q58: 0.115 | R58: 0.115 | S58: 0.115 | T58: 0.115 | U58: 0.115 | V58: 0.115 | W58: 0.115 | X58: 0.115 | Y58: 0.115 | Z58: 0.115 | AA58: 0.115 | AB58: 0.115 | AC58: 0.115 | AD58: 0.115 | AE58: 0.115 | AF58: 0.115 | AG58: 0.115 | AH58: 0.115 | AI58: 0.115 | AQ58: =AVERAGE(B58:AP58) -> 0.10626667
A59: 45992 | B59: 0.0743 | C59: 0.0743 | D59: 0.0743 | E59: 0.0743 | F59: 0.0743 | G59: 0.0743 | H59: 0.0732 | I59: 0.115 | J59: 0.115 | K59: 0.115 | L59: 0.115 | M59: 0.115 | N59: 0.115 | O59: 0.115 | P59: 0.115 | Q59: 0.115 | R59: 0.115 | S59: 0.115 | T59: 0.115 | U59: 0.115 | V59: 0.115 | W59: 0.115 | X59: 0.115 | Y59: 0.115 | Z59: 0.115 | AA59: 0.115 | AB59: 0.115 | AC59: 0.115 | AD59: 0.115 | AE59: 0.115 | AF59: 0.115 | AG59: 0.115 | AH59: 0.115 | AI59: 0.115 | AJ59: 0.115 | AQ59: =AVERAGE(B59:AP59) -> 0.10682857
A60: 46023 | B60: 0.0743 | C60: 0.0743 | D60: 0.0743 | E60: 0.0743 | F60: 0.0743 | G60: 0.0743 | H60: 0.0732 | I60: 0.115 | J60: 0.115 | K60: 0.115 | L60: 0.115 | M60: 0.115 | N60: 0.115 | O60: 0.115 | P60: 0.115 | Q60: 0.115 | R60: 0.115 | S60: 0.115 | T60: 0.115 | U60: 0.115 | V60: 0.115 | W60: 0.115 | X60: 0.115 | Y60: 0.115 | Z60: 0.115 | AA60: 0.115 | AB60: 0.115 | AC60: 0.115 | AD60: 0.115 | AE60: 0.115 | AF60: 0.115 | AG60: 0.115 | AH60: 0.115 | AI60: 0.115 | AJ60: 0.115 | AK60: 0.115 | AL60: 0.115 | AQ60: =AVERAGE(B60:AP60) -> 0.10727027
A61: 46054 | B61: 0.0743 | C61: 0.0743 | D61: 0.0743 | E61: 0.0743 | F61: 0.0743 | G61: 0.0743 | H61: 0.0732 | I61: 0.115 | J61: 0.115 | K61: 0.115 | L61: 0.115 | M61: 0.115 | N61: 0.115 | O61: 0.115 | P61: 0.115 | Q61: 0.115 | R61: 0.115 | S61: 0.115 | T61: 0.115 | U61: 0.115 | V61: 0.115 | W61: 0.115 | X61: 0.115 | Y61: 0.115 | Z61: 0.115 | AA61: 0.115 | AB61: 0.115 | AC61: 0.115 | AD61: 0.115 | AE61: 0.115 | AF61: 0.115 | AG61: 0.115 | AH61: 0.115 | AI61: 0.115 | AJ61: 0.115 | AK61: 0.115 | AL61: 0.115 | AN61: 0.115 | AQ61: =AVERAGE(B61:AP61) -> 0.10747368
A62: 46082 | B62: 0.0743 | C62: 0.0743 | D62: 0.0743 | E62: 0.0743 | F62: 0.0743 | G62: 0.0743 | H62: 0.0743 | I62: 0.115 | J62: 0.115 | K62: 0.115 | L62: 0.115 | M62: 0.115 | N62: 0.115 | O62: 0.115 | P62: 0.115 | Q62: 0.115 | R62: 0.115 | S62: 0.115 | T62: 0.115 | U62: 0.115 | V62: 0.115 | W62: 0.115 | X62: 0.115 | Y62: 0.115 | Z62: 0.115 | AA62: 0.115 | AB62: 0.115 | AC62: 0.115 | AD62: 0.115 | AE62: 0.115 | AF62: 0.115 | AG62: 0.115 | AH62: 0.115 | AI62: 0.115 | AJ62: 0.115 | AK62: 0.115 | AL62: 0.115 | AN62: 0.115 | AP62: 0.115 | AQ62: =AVERAGE(B62:AP62) -> 0.10769487
A63: 46113 | B63: 0.0754 | C63: 0.0754 | D63: 0.0754 | E63: 0.0743 | F63: 0.0743 | G63: 0.0743 | H63: 0.0743 | I63: 0.115 | J63: 0.115 | K63: 0.115 | L63: 0.115 | M63: 0.115 | N63: 0.115 | O63: 0.115 | P63: 0.115 | Q63: 0.115 | R63: 0.115 | S63: 0.115 | T63: 0.115 | U63: 0.115 | V63: 0.115 | W63: 0.115 | X63: 0.115 | Y63: 0.115 | Z63: 0.115 | AA63: 0.115 | AB63: 0.115 | AC63: 0.115 | AD63: 0.115 | AE63: 0.115 | AF63: 0.115 | AG63: 0.115 | AH63: 0.115 | AI63: 0.115 | AJ63: 0.115 | AK63: 0.115 | AL63: 0.115 | AN63: 0.115 | AO63: 0.115 | AP63: 0.115 | AQ63: =AVERAGE(B63:AP63) -> 0.10796
A64: 46143 | B64: 0.0754 | C64: 0.0754 | D64: 0.0754 | E64: 0.0743 | F64: 0.0743 | G64: 0.0743 | H64: 0.0743 | I64: 0.1173 | J64: 0.1173 | K64: 0.1173 | L64: 0.1173 | M64: 0.1173 | N64: 0.115 | O64: 0.115 | P64: 0.115 | Q64: 0.115 | R64: 0.115 | S64: 0.115 | T64: 0.115 | U64: 0.115 | V64: 0.115 | W64: 0.115 | X64: 0.115 | Y64: 0.115 | Z64: 0.115 | AA64: 0.115 | AB64: 0.115 | AC64: 0.115 | AD64: 0.115 | AE64: 0.115 | AF64: 0.115 | AG64: 0.115 | AH64: 0.115 | AI64: 0.115 | AJ64: 0.115 | AK64: 0.115 | AL64: 0.115 | AM64: 0.115 | AN64: 0.115 | AO64: 0.115 | AP64: 0.115 | AQ64: =AVERAGE(B64:AP64) -> 0.1084122
A65: 46174 | B65: 0.0754 | C65: 0.0754 | D65: 0.0754 | E65: 0.0743 | F65: 0.0743 | G65: 0.0743 | H65: 0.0743 | I65: 0.1173 | J65: 0.1173 | K65: 0.1173 | L65: 0.1173 | M65: 0.1173 | N65: 0.1173 | O65: 0.1173 | P65: 0.115 | Q65: 0.1173 | R65: 0.115 | S65: 0.115 | T65: 0.115 | U65: 0.115 | V65: 0.115 | W65: 0.115 | X65: 0.115 | Y65: 0.1173 | Z65: 0.115 | AA65: 0.1173 | AB65: 0.115 | AC65: 0.115 | AD65: 0.115 | AE65: 0.115 | AF65: 0.115 | AG65: 0.115 | AH65: 0.115 | AI65: 0.115 | AJ65: 0.115 | AK65: 0.115 | AL65: 0.115 | AM65: 0.115 | AN65: 0.115 | AO65: 0.115 | AP65: 0.115 | AQ65: =AVERAGE(B65:AP65) -> 0.10869268

Sheet Savings
B1: Monthly Cost Savings
A2: Month | B2: Alpharetta Library | C2: Wolf Creek Library | D2: Metropolitan Library | E2: Northwest Library | F2: Southeast Atlanta Library | G2: Neighbor-hood Union Health | H2: College Park Regional Health | I2: Milton Library | J2: E Roswell Library | K2: Maxwell Rd (Driver Services) | L2: Benson Senior Center | M2: Aviation Cultural Center | N2: Mill Senior Center | O2: Dogwood Library | P2: Palmetto Library | Q2: Cascade (SW) Library | R2: South Fulton Service Center | S2: Juvenile Justice Center | T2: Ponce de Leon Library | U2: New Beginnings Senior Center | V2: Medical Examiner | W2: Gladys Dennard Library | X2: Board of Health | Y2: Dogwood Senior Center | Z2: College Park Library | AA2: Animal Services | AB2: Adamsville Library | AC2: Union City Jail | AD2: Sandy Springs Library | AE2: QLS Senior Center | AF2: North Fulton Service Center | AG2: Bowden Senior Center | AH2: Cleveland Ave Library | AI2: Adams Park Library | AJ2: SE Neighborhood Senior Center | AK2: NE Spruill Oaks Library | AL2: Ocee Library | AM2: Auburn Ave Research Library | AN2: Buckhead Library | AO2: Hapeville Library | AP2: Northside Library | AQ2: Total Cost Savings | AR2: GRAND TOTAL
A3: 44287 | B3: =kWh!B3*('Elec Rates'!B3-'CS Rates'!B3) -> 387.468 | C3: =kWh!C3*('Elec Rates'!C3-'CS Rates'!C3) -> 317.976 | D3: =kWh!D3*('Elec Rates'!D3-'CS Rates'!D3) -> 239.9124 | E3: =kWh!E3*('Elec Rates'!E3-'CS Rates'!E3) -> 0 | F3: =kWh!F3*('Elec Rates'!F3-'CS Rates'!F3) -> 0 | G3: =kWh!G3*('Elec Rates'!G3-'CS Rates'!G3) -> 0 | H3: =kWh!H3*('Elec Rates'!H3-'CS Rates'!H3) -> 0 | I3: =kWh!I3*('Elec Rates'!I3-'CS Rates'!I3) -> 0 | ... AP3: =kWh!AP3*('Elec Rates'!AP3-'CS Rates'!AP3) -> 0 | AQ3: =SUM(B3:AP3) -> 945.3564 | AR3: =SUM(AQ3:AQ65) -> 326586.73
A4: 44317 | B4: =kWh!B4*('Elec Rates'!B4-'CS Rates'!B4) -> 718.524 | C4: =kWh!C4*('Elec Rates'!C4-'CS Rates'!C4) -> 259.756 | D4: =kWh!D4*('Elec Rates'!D4-'CS Rates'!D4) -> 488.418 | E4: =kWh!E4*('Elec Rates'!E4-'CS Rates'!E4) -> 0 | F4: =kWh!F4*('Elec Rates'!F4-'CS Rates'!F4) -> 0 | G4: =kWh!G4*('Elec Rates'!G4-'CS Rates'!G4) -> 0 | H4: =kWh!H4*('Elec Rates'!H4-'CS Rates'!H4) -> 0 | I4: =kWh!I4*('Elec Rates'!I4-'CS Rates'!I4) -> 0 | ... AP4: =kWh!AP4*('Elec Rates'!AP4-'CS Rates'!AP4) -> 0 | AQ4: =SUM(B4:AP4) -> 1466.698
A5: 44348 | B5: =kWh!B5*('Elec Rates'!B5-'CS Rates'!B5) -> 990.2592 | C5: =kWh!C5*('Elec Rates'!C5-'CS Rates'!C5) -> 413.85 | D5: =kWh!D5*('Elec Rates'!D5-'CS Rates'!D5) -> 926.31 | E5: =kWh!E5*('Elec Rates'!E5-'CS Rates'!E5) -> 0 | F5: =kWh!F5*('Elec Rates'!F5-'CS Rates'!F5) -> 0 | G5: =kWh!G5*('Elec Rates'!G5-'CS Rates'!G5) -> 0 | H5: =kWh!H5*('Elec Rates'!H5-'CS Rates'!H5) -> 0 | I5: =kWh!I5*('Elec Rates'!I5-'CS Rates'!I5) -> 0 | ... AP5: =kWh!AP5*('Elec Rates'!AP5-'CS Rates'!AP5) -> 0 | AQ5: =SUM(B5:AP5) -> 2330.4192
A6: 44378 | B6: =kWh!B6*('Elec Rates'!B6-'CS Rates'!B6) -> 573.3376 | C6: =kWh!C6*('Elec Rates'!C6-'CS Rates'!C6) -> 519.8725 | D6: =kWh!D6*('Elec Rates'!D6-'CS Rates'!D6) -> 660.5837 | E6: =kWh!E6*('Elec Rates'!E6-'CS Rates'!E6) -> 0 | F6: =kWh!F6*('Elec Rates'!F6-'CS Rates'!F6) -> 0 | G6: =kWh!G6*('Elec Rates'!G6-'CS Rates'!G6) -> 0 | H6: =kWh!H6*('Elec Rates'!H6-'CS Rates'!H6) -> 0 | I6: =kWh!I6*('Elec Rates'!I6-'CS Rates'!I6) -> 0 | ... AP6: =kWh!AP6*('Elec Rates'!AP6-'CS Rates'!AP6) -> 0 | AQ6: =SUM(B6:AP6) -> 1753.7938
A7: 44409 | B7: =kWh!B7*('Elec Rates'!B7-'CS Rates'!B7) -> 835.5382 | C7: =kWh!C7*('Elec Rates'!C7-'CS Rates'!C7) -> 379.3426 | D7: =kWh!D7*('Elec Rates'!D7-'CS Rates'!D7) -> 1069.992 | E7: =kWh!E7*('Elec Rates'!E7-'CS Rates'!E7) -> 0 | F7: =kWh!F7*('Elec Rates'!F7-'CS Rates'!F7) -> 0 | G7: =kWh!G7*('Elec Rates'!G7-'CS Rates'!G7) -> 0 | H7: =kWh!H7*('Elec Rates'!H7-'CS Rates'!H7) -> 0 | I7: =kWh!I7*('Elec Rates'!I7-'CS Rates'!I7) -> 0 | ... AP7: =kWh!AP7*('Elec Rates'!AP7-'CS Rates'!AP7) -> 0 | AQ7: =SUM(B7:AP7) -> 2284.8728
A8: 44440 | B8: =kWh!B8*('Elec Rates'!B8-'CS Rates'!B8) -> 747.45 | C8: =kWh!C8*('Elec Rates'!C8-'CS Rates'!C8) -> 74.984 | D8: =kWh!D8*('Elec Rates'!D8-'CS Rates'!D8) -> 764.345 | E8: =kWh!E8*('Elec Rates'!E8-'CS Rates'!E8) -> 0 | F8: =kWh!F8*('Elec Rates'!F8-'CS Rates'!F8) -> 0 | G8: =kWh!G8*('Elec Rates'!G8-'CS Rates'!G8) -> 0 | H8: =kWh!H8*('Elec Rates'!H8-'CS Rates'!H8) -> 0 | I8: =kWh!I8*('Elec Rates'!I8-'CS Rates'!I8) -> 0 | ... AP8: =kWh!AP8*('Elec Rates'!AP8-'CS Rates'!AP8) -> 0 | AQ8: =SUM(B8:AP8) -> 1586.779
A9: 44470 | B9: =kWh!B9*('Elec Rates'!B9-'CS Rates'!B9) -> 161.784 | C9: =kWh!C9*('Elec Rates'!C9-'CS Rates'!C9) -> 426.972 | D9: =kWh!D9*('Elec Rates'!D9-'CS Rates'!D9) -> 194.994 | E9: =kWh!E9*('Elec Rates'!E9-'CS Rates'!E9) -> 276.192 | F9: =kWh!F9*('Elec Rates'!F9-'CS Rates'!F9) -> 0 | G9: =kWh!G9*('Elec Rates'!G9-'CS Rates'!G9) -> 0 | H9: =kWh!H9*('Elec Rates'!H9-'CS Rates'!H9) -> 0 | I9: =kWh!I9*('Elec Rates'!I9-'CS Rates'!I9) -> 0 | ... AP9: =kWh!AP9*('Elec Rates'!AP9-'CS Rates'!AP9) -> 0 | AQ9: =SUM(B9:AP9) -> 1059.942
A10: 44501 | B10: =kWh!B10*('Elec Rates'!B10-'CS Rates'!B10) -> 119.52 | C10: =kWh!C10*('Elec Rates'!C10-'CS Rates'!C10) -> 276.544 | D10: =kWh!D10*('Elec Rates'!D10-'CS Rates'!D10) -> 186.894 | E10: =kWh!E10*('Elec Rates'!E10-'CS Rates'!E10) -> 270.336 | F10: =kWh!F10*('Elec Rates'!F10-'CS Rates'!F10) -> 0 | G10: =kWh!G10*('Elec Rates'!G10-'CS Rates'!G10) -> 0 | H10: =kWh!H10*('Elec Rates'!H10-'CS Rates'!H10) -> 0 | I10: =kWh!I10*('Elec Rates'!I10-'CS Rates'!I10) -> 0 | ... AP10: =kWh!AP10*('Elec Rates'!AP10-'CS Rates'!AP10) -> 0 | AQ10: =SUM(B10:AP10) -> 853.294
A11: 44531 | B11: =kWh!B11*('Elec Rates'!B11-'CS Rates'!B11) -> 82.392 | C11: =kWh!C11*('Elec Rates'!C11-'CS Rates'!C11) -> 137.75 | D11: =kWh!D11*('Elec Rates'!D11-'CS Rates'!D11) -> 99.28 | E11: =kWh!E11*('Elec Rates'!E11-'CS Rates'!E11) -> 178.828 | F11: =kWh!F11*('Elec Rates'!F11-'CS Rates'!F11) -> 164.865 | G11: =kWh!G11*('Elec Rates'!G11-'CS Rates'!G11) -> 99.862 | H11: =kWh!H11*('Elec Rates'!H11-'CS Rates'!H11) -> 0 | I11: =kWh!I11*('Elec Rates'!I11-'CS Rates'!I11) -> 0 | ... AP11: =kWh!AP11*('Elec Rates'!AP11-'CS Rates'!AP11) -> 0 | AQ11: =SUM(B11:AP11) -> 762.977
A12: 44562 | B12: =kWh!B12*('Elec Rates'!B12-'CS Rates'!B12) -> 212.872 | C12: =kWh!C12*('Elec Rates'!C12-'CS Rates'!C12) -> 214.162 | D12: =kWh!D12*('Elec Rates'!D12-'CS Rates'!D12) -> 154.872 | E12: =kWh!E12*('Elec Rates'!E12-'CS Rates'!E12) -> 567.932 | F12: =kWh!F12*('Elec Rates'!F12-'CS Rates'!F12) -> 252.798 | G12: =kWh!G12*('Elec Rates'!G12-'CS Rates'!G12) -> 50.028 | H12: =kWh!H12*('Elec Rates'!H12-'CS Rates'!H12) -> 0 | I12: =kWh!I12*('Elec Rates'!I12-'CS Rates'!I12) -> 0 | ... AP12: =kWh!AP12*('Elec Rates'!AP12-'CS Rates'!AP12) -> 0 | AQ12: =SUM(B12:AP12) -> 1452.664
A13: 44593 | B13: =kWh!B13*('Elec Rates'!B13-'CS Rates'!B13) -> 257.004 | C13: =kWh!C13*('Elec Rates'!C13-'CS Rates'!C13) -> 349.65 | D13: =kWh!D13*('Elec Rates'!D13-'CS Rates'!D13) -> 171.288 | E13: =kWh!E13*('Elec Rates'!E13-'CS Rates'!E13) -> 644.684 | F13: =kWh!F13*('Elec Rates'!F13-'CS Rates'!F13) -> 274.684 | G13: =kWh!G13*('Elec Rates'!G13-'CS Rates'!G13) -> 148.984 | H13: =kWh!H13*('Elec Rates'!H13-'CS Rates'!H13) -> 0 | I13: =kWh!I13*('Elec Rates'!I13-'CS Rates'!I13) -> 0 | ... AP13: =kWh!AP13*('Elec Rates'!AP13-'CS Rates'!AP13) -> 0 | AQ13: =SUM(B13:AP13) -> 1846.294
A14: 44621 | B14: =kWh!B14*('Elec Rates'!B14-'CS Rates'!B14) -> 429.208 | C14: =kWh!C14*('Elec Rates'!C14-'CS Rates'!C14) -> 579.306 | D14: =kWh!D14*('Elec Rates'!D14-'CS Rates'!D14) -> 249.642 | E14: =kWh!E14*('Elec Rates'!E14-'CS Rates'!E14) -> 253.874 | F14: =kWh!F14*('Elec Rates'!F14-'CS Rates'!F14) -> 442.47 | G14: =kWh!G14*('Elec Rates'!G14-'CS Rates'!G14) -> 76.608 | H14: =kWh!H14*('Elec Rates'!H14-'CS Rates'!H14) -> 513.432 | I14: =kWh!I14*('Elec Rates'!I14-'CS Rates'!I14) -> 0 | ... AP14: =kWh!AP14*('Elec Rates'!AP14-'CS Rates'!AP14) -> 0 | AQ14: =SUM(B14:AP14) -> 2544.54
A15: 44652 | B15: =kWh!B15*('Elec Rates'!B15-'CS Rates'!B15) -> 444.8151 | C15: =kWh!C15*('Elec Rates'!C15-'CS Rates'!C15) -> 363.9032 | D15: =kWh!D15*('Elec Rates'!D15-'CS Rates'!D15) -> 252.3677 | E15: =kWh!E15*('Elec Rates'!E15-'CS Rates'!E15) -> 240.5 | F15: =kWh!F15*('Elec Rates'!F15-'CS Rates'!F15) -> 503.258 | G15: =kWh!G15*('Elec Rates'!G15-'CS Rates'!G15) -> 83.094 | H15: =kWh!H15*('Elec Rates'!H15-'CS Rates'!H15) -> 1388.8 | I15: =kWh!I15*('Elec Rates'!I15-'CS Rates'!I15) -> 0 | ... AP15: =kWh!AP15*('Elec Rates'!AP15-'CS Rates'!AP15) -> 0 | AQ15: =SUM(B15:AP15) -> 3276.738
... A26: 44986 | B26: =kWh!B26*('Elec Rates'!B26-'CS Rates'!B26) -> 227.2077 | C26: =kWh!C26*('Elec Rates'!C26-'CS Rates'!C26) -> 776.5767 | D26: =kWh!D26*('Elec Rates'!D26-'CS Rates'!D26) -> 270.7497 | E26: =kWh!E26*('Elec Rates'!E26-'CS Rates'!E26) -> 186.0138 | F26: =kWh!F26*('Elec Rates'!F26-'CS Rates'!F26) -> 440.5149 | G26: =kWh!G26*('Elec Rates'!G26-'CS Rates'!G26) -> 63.9262 | H26: =kWh!H26*('Elec Rates'!H26-'CS Rates'!H26) -> 870.0708 | I26: =kWh!I26*('Elec Rates'!I26-'CS Rates'!I26) -> 0 | ... AP26: =kWh!AP26*('Elec Rates'!AP26-'CS Rates'!AP26) -> 0 | AQ26: =SUM(B26:AP26) -> 2835.0598
A27: 45017 | B27: =kWh!B27*('Elec Rates'!B27-'CS Rates'!B27) -> 282.5155 | C27: =kWh!C27*('Elec Rates'!C27-'CS Rates'!C27) -> 477.3419 | D27: =kWh!D27*('Elec Rates'!D27-'CS Rates'!D27) -> 359.1957 | E27: =kWh!E27*('Elec Rates'!E27-'CS Rates'!E27) -> 165.8847 | F27: =kWh!F27*('Elec Rates'!F27-'CS Rates'!F27) -> 456.8993 | G27: =kWh!G27*('Elec Rates'!G27-'CS Rates'!G27) -> 73.689 | H27: =kWh!H27*('Elec Rates'!H27-'CS Rates'!H27) -> 1000.2906 | I27: =kWh!I27*('Elec Rates'!I27-'CS Rates'!I27) -> 0 | ... AP27: =kWh!AP27*('Elec Rates'!AP27-'CS Rates'!AP27) -> 0 | AQ27: =SUM(B27:AP27) -> 2815.8167 | AT27: 6720 | AU27: per year
A28: 45047 | B28: =kWh!B28*('Elec Rates'!B28-'CS Rates'!B28) -> 289.8161 | C28: =kWh!C28*('Elec Rates'!C28-'CS Rates'!C28) -> 364.9908 | D28: =kWh!D28*('Elec Rates'!D28-'CS Rates'!D28) -> 292.7463 | E28: =kWh!E28*('Elec Rates'!E28-'CS Rates'!E28) -> 162.1567 | F28: =kWh!F28*('Elec Rates'!F28-'CS Rates'!F28) -> 470.1346 | G28: =kWh!G28*('Elec Rates'!G28-'CS Rates'!G28) -> 71.9032 | H28: =kWh!H28*('Elec Rates'!H28-'CS Rates'!H28) -> 1044.7786 | I28: =kWh!I28*('Elec Rates'!I28-'CS Rates'!I28) -> 0 | ... AP28: =kWh!AP28*('Elec Rates'!AP28-'CS Rates'!AP28) -> 0 | AQ28: =SUM(B28:AP28) -> 2696.5263 | AT28: 17 | AU28: years
A29: 45078 | B29: =kWh!B29*('Elec Rates'!B29-'CS Rates'!B29) -> 919.9872 | C29: =kWh!C29*('Elec Rates'!C29-'CS Rates'!C29) -> 405.0319 | D29: =kWh!D29*('Elec Rates'!D29-'CS Rates'!D29) -> 1099.7922 | E29: =kWh!E29*('Elec Rates'!E29-'CS Rates'!E29) -> 769.3374 | F29: =kWh!F29*('Elec Rates'!F29-'CS Rates'!F29) -> 421.8681 | G29: =kWh!G29*('Elec Rates'!G29-'CS Rates'!G29) -> 250.536 | H29: =kWh!H29*('Elec Rates'!H29-'CS Rates'!H29) -> 989.4423 | I29: =kWh!I29*('Elec Rates'!I29-'CS Rates'!I29) -> 0 | ... AP29: =kWh!AP29*('Elec Rates'!AP29-'CS Rates'!AP29) -> 0 | AQ29: =SUM(B29:AP29) -> 4855.9951 | AT29: =AT27*AT28 -> 114240
A30: 45108 | B30: =kWh!B30*('Elec Rates'!B30-'CS Rates'!B30) -> 945.7539 | C30: =kWh!C30*('Elec Rates'!C30-'CS Rates'!C30) -> 495.4082 | D30: =kWh!D30*('Elec Rates'!D30-'CS Rates'!D30) -> 1381.2606 | E30: =kWh!E30*('Elec Rates'!E30-'CS Rates'!E30) -> 1075.9567 | F30: =kWh!F30*('Elec Rates'!F30-'CS Rates'!F30) -> 646.7406 | G30: =kWh!G30*('Elec Rates'!G30-'CS Rates'!G30) -> 307.8171 | H30: =kWh!H30*('Elec Rates'!H30-'CS Rates'!H30) -> 1158.0107 | I30: =kWh!I30*('Elec Rates'!I30-'CS Rates'!I30) -> 0 | ... AP30: =kWh!AP30*('Elec Rates'!AP30-'CS Rates'!AP30) -> 0 | AQ30: =SUM(B30:AP30) -> 6010.9478
A31: 45139 | B31: =kWh!B31*('Elec Rates'!B31-'CS Rates'!B31) -> 961.9701 | C31: =kWh!C31*('Elec Rates'!C31-'CS Rates'!C31) -> 410.7662 | D31: =kWh!D31*('Elec Rates'!D31-'CS Rates'!D31) -> 1211.4378 | E31: =kWh!E31*('Elec Rates'!E31-'CS Rates'!E31) -> 1180.426 | F31: =kWh!F31*('Elec Rates'!F31-'CS Rates'!F31) -> 642.6168 | G31: =kWh!G31*('Elec Rates'!G31-'CS Rates'!G31) -> 314.4582 | H31: =kWh!H31*('Elec Rates'!H31-'CS Rates'!H31) -> 932.19 | I31: =kWh!I31*('Elec Rates'!I31-'CS Rates'!I31) -> 0 | ... AP31: =kWh!AP31*('Elec Rates'!AP31-'CS Rates'!AP31) -> 0 | AQ31: =SUM(B31:AP31) -> 5653.8651
A32: 45170 | B32: =kWh!B32*('Elec Rates'!B32-'CS Rates'!B32) -> 909.3021 | C32: =kWh!C32*('Elec Rates'!C32-'CS Rates'!C32) -> 400.0337 | D32: =kWh!D32*('Elec Rates'!D32-'CS Rates'!D32) -> 984.6862 | E32: =kWh!E32*('Elec Rates'!E32-'CS Rates'!E32) -> 1101.7761 | F32: =kWh!F32*('Elec Rates'!F32-'CS Rates'!F32) -> 534.4086 | G32: =kWh!G32*('Elec Rates'!G32-'CS Rates'!G32) -> 272.835 | H32: =kWh!H32*('Elec Rates'!H32-'CS Rates'!H32) -> 807.9313 | I32: =kWh!I32*('Elec Rates'!I32-'CS Rates'!I32) -> 0 | ... AP32: =kWh!AP32*('Elec Rates'!AP32-'CS Rates'!AP32) -> 0 | AQ32: =SUM(B32:AP32) -> 5010.973
A33: 45200 | B33: =kWh!B33*('Elec Rates'!B33-'CS Rates'!B33) -> 293.0312 | C33: =kWh!C33*('Elec Rates'!C33-'CS Rates'!C33) -> 291.2634 | D33: =kWh!D33*('Elec Rates'!D33-'CS Rates'!D33) -> 317.5902 | E33: =kWh!E33*('Elec Rates'!E33-'CS Rates'!E33) -> 356.1129 | F33: =kWh!F33*('Elec Rates'!F33-'CS Rates'!F33) -> 453.728 | G33: =kWh!G33*('Elec Rates'!G33-'CS Rates'!G33) -> 84.7712 | H33: =kWh!H33*('Elec Rates'!H33-'CS Rates'!H33) -> 811.3149 | I33: =kWh!I33*('Elec Rates'!I33-'CS Rates'!I33) -> 0 | ... AP33: =kWh!AP33*('Elec Rates'!AP33-'CS Rates'!AP33) -> 0 | AQ33: =SUM(B33:AP33) -> 2607.8118
A34: 45231 | B34: =kWh!B34*('Elec Rates'!B34-'CS Rates'!B34) -> 194.1227 | C34: =kWh!C34*('Elec Rates'!C34-'CS Rates'!C34) -> 182.5432 | D34: =kWh!D34*('Elec Rates'!D34-'CS Rates'!D34) -> 256.6858 | E34: =kWh!E34*('Elec Rates'!E34-'CS Rates'!E34) -> 308.2323 | F34: =kWh!F34*('Elec Rates'!F34-'CS Rates'!F34) -> 341.4561 | G34: =kWh!G34*('Elec Rates'!G34-'CS Rates'!G34) -> 60.6177 | H34: =kWh!H34*('Elec Rates'!H34-'CS Rates'!H34) -> 545.2962 | I34: =kWh!I34*('Elec Rates'!I34-'CS Rates'!I34) -> 0 | ... AP34: =kWh!AP34*('Elec Rates'!AP34-'CS Rates'!AP34) -> 0 | AQ34: =SUM(B34:AP34) -> 1888.954
A35: 45261 | B35: =kWh!B35*('Elec Rates'!B35-'CS Rates'!B35) -> 129.5319 | C35: =kWh!C35*('Elec Rates'!C35-'CS Rates'!C35) -> 174.7872 | D35: =kWh!D35*('Elec Rates'!D35-'CS Rates'!D35) -> 235.6476 | E35: =kWh!E35*('Elec Rates'!E35-'CS Rates'!E35) -> 260.9134 | F35: =kWh!F35*('Elec Rates'!F35-'CS Rates'!F35) -> 258.6726 | G35: =kWh!G35*('Elec Rates'!G35-'CS Rates'!G35) -> 54.1161 | H35: =kWh!H35*('Elec Rates'!H35-'CS Rates'!H35) -> 416.8089 | I35: =kWh!I35*('Elec Rates'!I35-'CS Rates'!I35) -> 0 | ... AP35: =kWh!AP35*('Elec Rates'!AP35-'CS Rates'!AP35) -> 0 | AQ35: =SUM(B35:AP35) -> 1530.4777
A36: 45292 | B36: =kWh!B36*('Elec Rates'!B36-'CS Rates'!B36) -> 131.6796 | C36: =kWh!C36*('Elec Rates'!C36-'CS Rates'!C36) -> 220.2135 | D36: =kWh!D36*('Elec Rates'!D36-'CS Rates'!D36) -> 302.0829 | E36: =kWh!E36*('Elec Rates'!E36-'CS Rates'!E36) -> 240.6556 | F36: =kWh!F36*('Elec Rates'!F36-'CS Rates'!F36) -> 210.8976 | G36: =kWh!G36*('Elec Rates'!G36-'CS Rates'!G36) -> 61.4681 | H36: =kWh!H36*('Elec Rates'!H36-'CS Rates'!H36) -> 564.0558 | I36: =kWh!I36*('Elec Rates'!I36-'CS Rates'!I36) -> 0 | ... AP36: =kWh!AP36*('Elec Rates'!AP36-'CS Rates'!AP36) -> 0 | AQ36: =SUM(B36:AP36) -> 1731.0531
A37: 45323 | B37: =kWh!B37*('Elec Rates'!B37-'CS Rates'!B37) -> 176.1466 | C37: =kWh!C37*('Elec Rates'!C37-'CS Rates'!C37) -> 249.054 | D37: =kWh!D37*('Elec Rates'!D37-'CS Rates'!D37) -> 335.1118 | E37: =kWh!E37*('Elec Rates'!E37-'CS Rates'!E37) -> 299.3562 | F37: =kWh!F37*('Elec Rates'!F37-'CS Rates'!F37) -> 360.5393 | G37: =kWh!G37*('Elec Rates'!G37-'CS Rates'!G37) -> 84.1379 | H37: =kWh!H37*('Elec Rates'!H37-'CS Rates'!H37) -> 626.4174 | I37: =kWh!I37*('Elec Rates'!I37-'CS Rates'!I37) -> 0 | ... AP37: =kWh!AP37*('Elec Rates'!AP37-'CS Rates'!AP37) -> 0 | AQ37: =SUM(B37:AP37) -> 2130.7632
A38: 45352 | B38: =kWh!B38*('Elec Rates'!B38-'CS Rates'!B38) -> 261.2447 | C38: =kWh!C38*('Elec Rates'!C38-'CS Rates'!C38) -> 437.3941 | D38: =kWh!D38*('Elec Rates'!D38-'CS Rates'!D38) -> 384.0192 | E38: =kWh!E38*('Elec Rates'!E38-'CS Rates'!E38) -> 403.6061 | F38: =kWh!F38*('Elec Rates'!F38-'CS Rates'!F38) -> 472.3047 | G38: =kWh!G38*('Elec Rates'!G38-'CS Rates'!G38) -> 107.4766 | H38: =kWh!H38*('Elec Rates'!H38-'CS Rates'!H38) -> 831.6585 | I38: =kWh!I38*('Elec Rates'!I38-'CS Rates'!I38) -> 0 | ... AP38: =kWh!AP38*('Elec Rates'!AP38-'CS Rates'!AP38) -> 0 | AQ38: =SUM(B38:AP38) -> 2897.7039
A39: 45383 | B39: =kWh!B39*('Elec Rates'!B39-'CS Rates'!B39) -> 360.217 | C39: =kWh!C39*('Elec Rates'!C39-'CS Rates'!C39) -> 470.3454 | D39: =kWh!D39*('Elec Rates'!D39-'CS Rates'!D39) -> 418.4562 | E39: =kWh!E39*('Elec Rates'!E39-'CS Rates'!E39) -> 440.9556 | F39: =kWh!F39*('Elec Rates'!F39-'CS Rates'!F39) -> 572.992 | G39: =kWh!G39*('Elec Rates'!G39-'CS Rates'!G39) -> 117.2736 | H39: =kWh!H39*('Elec Rates'!H39-'CS Rates'!H39) -> 989.172 | I39: =kWh!I39*('Elec Rates'!I39-'CS Rates'!I39) -> 0 | ... AP39: =kWh!AP39*('Elec Rates'!AP39-'CS Rates'!AP39) -> 0 | AQ39: =SUM(B39:AP39) -> 3369.4118
A40: 45413 | B40: =kWh!B40*('Elec Rates'!B40-'CS Rates'!B40) -> 368.256 | C40: =kWh!C40*('Elec Rates'!C40-'CS Rates'!C40) -> 580.0168 | D40: =kWh!D40*('Elec Rates'!D40-'CS Rates'!D40) -> 490.6452 | E40: =kWh!E40*('Elec Rates'!E40-'CS Rates'!E40) -> 611.1468 | F40: =kWh!F40*('Elec Rates'!F40-'CS Rates'!F40) -> 627.9603 | G40: =kWh!G40*('Elec Rates'!G40-'CS Rates'!G40) -> 103.0458 | H40: =kWh!H40*('Elec Rates'!H40-'CS Rates'!H40) -> 1059.0363 | I40: =kWh!I40*('Elec Rates'!I40-'CS Rates'!I40) -> 0 | ... AP40: =kWh!AP40*('Elec Rates'!AP40-'CS Rates'!AP40) -> 0 | AQ40: =SUM(B40:AP40) -> 3840.1072
A41: 45444 | B41: =kWh!B41*('Elec Rates'!B41-'CS Rates'!B41) -> 1354.8588 | C41: =kWh!C41*('Elec Rates'!C41-'CS Rates'!C41) -> 616.701 | D41: =kWh!D41*('Elec Rates'!D41-'CS Rates'!D41) -> 1489.7904 | E41: =kWh!E41*('Elec Rates'!E41-'CS Rates'!E41) -> 1840.8271 | F41: =kWh!F41*('Elec Rates'!F41-'CS Rates'!F41) -> 735.5063 | G41: =kWh!G41*('Elec Rates'!G41-'CS Rates'!G41) -> 392.1147 | H41: =kWh!H41*('Elec Rates'!H41-'CS Rates'!H41) -> 1169.0775 | I41: =kWh!I41*('Elec Rates'!I41-'CS Rates'!I41) -> 0 | ... AP41: =kWh!AP41*('Elec Rates'!AP41-'CS Rates'!AP41) -> 0 | AQ41: =SUM(B41:AP41) -> 7598.8758
... A65: 46174 | B65: =kWh!B65*('Elec Rates'!B65-'CS Rates'!B65) -> 918.4782 | C65: =kWh!C65*('Elec Rates'!C65-'CS Rates'!C65) -> 520.269 | D65: =kWh!D65*('Elec Rates'!D65-'CS Rates'!D65) -> 1411.3604 | E65: =kWh!E65*('Elec Rates'!E65-'CS Rates'!E65) -> 1593.7089 | F65: =kWh!F65*('Elec Rates'!F65-'CS Rates'!F65) -> 635.4953 | G65: =kWh!G65*('Elec Rates'!G65-'CS Rates'!G65) -> 331.5077 | H65: =kWh!H65*('Elec Rates'!H65-'CS Rates'!H65) -> 689.3187 | I65: =kWh!I65*('Elec Rates'!I65-'CS Rates'!I65) -> 27.9457 | ... AP65: =kWh!AP65*('Elec Rates'!AP65-'CS Rates'!AP65) -> 377.19 | AQ65: =SUM(B65:AP65) -> 18959.772

Sheet Graphs
A1: Month | B1: Total kWh Produced | C1: Total Cost Savings
A2: 44287 | B2: 22558.3 | C2: 945.3564
A3: 44317 | B3: 34844.6 | C3: 1466.698
A4: 44348 | B4: 38075.1 | C4: 2330.4192
A5: 44378 | B5: 37293.2 | C5: 1753.7938
A6: 44409 | B6: 40100 | C6: 2284.8728
A7: 44440 | B7: 26273 | C7: 1586.779
A8: 44470 | B8: 35622 | C8: 1059.942
A9: 44501 | B9: 34343 | C9: 853.294
A10: 44531 | B10: 22403 | C10: 762.977
A11: 44562 | B11: 32899 | C11: 1452.664
A12: 44593 | B12: 37556 | C12: 1846.294
A13: 44621 | B13: 60994 | C13: 2544.54
... A58: 45992 | B58: 181659 | C58: 8162.8995
